Traceback (most recent call last):
  File "/n/holylabs/LABS/dam_lab/Lab/sqin/envs/reason/lib/python3.11/site-packages/huggingface_hub/utils/_errors.py", line 304, in hf_raise_for_status
    response.raise_for_status()
  File "/n/holylabs/LABS/dam_lab/Lab/sqin/envs/reason/lib/python3.11/site-packages/requests/models.py", line 1024, in raise_for_status
    raise HTTPError(http_error_msg, response=self)
requests.exceptions.HTTPError: 404 Client Error: Not Found for url: https://huggingface.co/Qwen/Qwen-0.5B/resolve/main/config.json
The above exception was the direct cause of the following exception:
Traceback (most recent call last):
  File "/n/holylabs/LABS/dam_lab/Lab/sqin/envs/reason/lib/python3.11/site-packages/transformers/utils/hub.py", line 403, in cached_file
    resolved_file = hf_hub_download(
                    ^^^^^^^^^^^^^^^^
  File "/n/holylabs/LABS/dam_lab/Lab/sqin/envs/reason/lib/python3.11/site-packages/huggingface_hub/utils/_deprecation.py", line 101, in inner_f
    return f(*args, **kwargs)
           ^^^^^^^^^^^^^^^^^^
  File "/n/holylabs/LABS/dam_lab/Lab/sqin/envs/reason/lib/python3.11/site-packages/huggingface_hub/utils/_validators.py", line 114, in _inner_fn
    return fn(*args, **kwargs)
           ^^^^^^^^^^^^^^^^^^^
  File "/n/holylabs/LABS/dam_lab/Lab/sqin/envs/reason/lib/python3.11/site-packages/huggingface_hub/file_download.py", line 1240, in hf_hub_download
    return _hf_hub_download_to_cache_dir(
           ^^^^^^^^^^^^^^^^^^^^^^^^^^^^^^
  File "/n/holylabs/LABS/dam_lab/Lab/sqin/envs/reason/lib/python3.11/site-packages/huggingface_hub/file_download.py", line 1347, in _hf_hub_download_to_cache_dir
    _raise_on_head_call_error(head_call_error, force_download, local_files_only)
  File "/n/holylabs/LABS/dam_lab/Lab/sqin/envs/reason/lib/python3.11/site-packages/huggingface_hub/file_download.py", line 1854, in _raise_on_head_call_error
    raise head_call_error
  File "/n/holylabs/LABS/dam_lab/Lab/sqin/envs/reason/lib/python3.11/site-packages/huggingface_hub/file_download.py", line 1751, in _get_metadata_or_catch_error
    metadata = get_hf_file_metadata(
               ^^^^^^^^^^^^^^^^^^^^^
  File "/n/holylabs/LABS/dam_lab/Lab/sqin/envs/reason/lib/python3.11/site-packages/huggingface_hub/utils/_validators.py", line 114, in _inner_fn
    return fn(*args, **kwargs)
           ^^^^^^^^^^^^^^^^^^^
  File "/n/holylabs/LABS/dam_lab/Lab/sqin/envs/reason/lib/python3.11/site-packages/huggingface_hub/file_download.py", line 1673, in get_hf_file_metadata
    r = _request_wrapper(
        ^^^^^^^^^^^^^^^^^
  File "/n/holylabs/LABS/dam_lab/Lab/sqin/envs/reason/lib/python3.11/site-packages/huggingface_hub/file_download.py", line 376, in _request_wrapper
    response = _request_wrapper(
               ^^^^^^^^^^^^^^^^^
  File "/n/holylabs/LABS/dam_lab/Lab/sqin/envs/reason/lib/python3.11/site-packages/huggingface_hub/file_download.py", line 400, in _request_wrapper
    hf_raise_for_status(response)
  File "/n/holylabs/LABS/dam_lab/Lab/sqin/envs/reason/lib/python3.11/site-packages/huggingface_hub/utils/_errors.py", line 352, in hf_raise_for_status
    raise RepositoryNotFoundError(message, response) from e
huggingface_hub.utils._errors.RepositoryNotFoundError: 404 Client Error. (Request ID: Root=1-678820cb-713a027d214520b72a33f57b;7a4f8ed1-cc54-4a5c-a0ae-d2174eae0261)
Repository Not Found for url: https://huggingface.co/Qwen/Qwen-0.5B/resolve/main/config.json.
Please make sure you specified the correct `repo_id` and `repo_type`.
If you are trying to access a private or gated repo, make sure you are authenticated.
The above exception was the direct cause of the following exception:
Traceback (most recent call last):
  File "/n/home05/sqin/self-correct/sudoku/train.py", line 189, in <module>
    main(args)
  File "/n/home05/sqin/self-correct/sudoku/train.py", line 62, in main
    config = AutoConfig.from_pretrained("Qwen/Qwen-0.5B")
             ^^^^^^^^^^^^^^^^^^^^^^^^^^^^^^^^^^^^^^^^^^^^
  File "/n/holylabs/LABS/dam_lab/Lab/sqin/envs/reason/lib/python3.11/site-packages/transformers/models/auto/configuration_auto.py", line 1054, in from_pretrained
    config_dict, unused_kwargs = PretrainedConfig.get_config_dict(pretrained_model_name_or_path, **kwargs)
                                 ^^^^^^^^^^^^^^^^^^^^^^^^^^^^^^^^^^^^^^^^^^^^^^^^^^^^^^^^^^^^^^^^^^^^^^^^^
  File "/n/holylabs/LABS/dam_lab/Lab/sqin/envs/reason/lib/python3.11/site-packages/transformers/configuration_utils.py", line 591, in get_config_dict
    config_dict, kwargs = cls._get_config_dict(pretrained_model_name_or_path, **kwargs)
                          ^^^^^^^^^^^^^^^^^^^^^^^^^^^^^^^^^^^^^^^^^^^^^^^^^^^^^^^^^^^^^
  File "/n/holylabs/LABS/dam_lab/Lab/sqin/envs/reason/lib/python3.11/site-packages/transformers/configuration_utils.py", line 650, in _get_config_dict
    resolved_config_file = cached_file(
                           ^^^^^^^^^^^^
  File "/n/holylabs/LABS/dam_lab/Lab/sqin/envs/reason/lib/python3.11/site-packages/transformers/utils/hub.py", line 426, in cached_file
    raise EnvironmentError(
OSError: Qwen/Qwen-0.5B is not a local folder and is not a valid model identifier listed on 'https://huggingface.co/models'
If this is a private repository, make sure to pass a token having permission to this repo either by logging in with `huggingface-cli login` or by passing `token=<your_token>`